Workbook
Name Slicer_Age_Group: #N/A
Name Slicer_Attrition: #N/A
Name Slicer_Department: #N/A
Name Slicer_Employment_Status: #N/A
Name Slicer_Hire_year: #N/A
Name Slicer_Salary_bamd: #N/A

Sheet Raw_HR_Data
A1: Employee_ID | B1: Full_Name | C1: Department | D1: Job_Title | E1: Gender | F1: Age | G1: Date_Hired | H1: Date_Left | I1: Employment_Status | J1: Salary_NGN | K1: Performance_Score | L1: Years_Experience | M1: Education_Level | N1: Attrition
A2: EMP-4001 | B2: Jide Garba | C2: Marketing | D2: Director | E2: Male | F2: 29 | G2: 22-08-2020 | I2: Active | J2: 872210.52 | K2: 5 | L2: 4.8 | M2: OND | N2: No
A3: EMP-4002 | B3: Tayo Okonkwo | C3: Operations | D3: Analyst | E3: Female | F3: 33 | G3: 12-06-2023 | H3: 12-10-2026 | I3: Terminated | J3: 339681.12 | K3: 3 | L3: 2.3 | M3: OND | N3: Yes
A4: EMP-4003 | B4: Jide Musa | C4: Marketing | D4: Director | E4: Male | F4: 26 | G4: 16-06-2019 | H4: 09-11-2023 | I4: Terminated | J4: 925355.42 | K4: 5 | L4: 1.5 | M4: MSc | N4: Yes
A5: EMP-4004 | B5: Emeka Mohammed | C5: HR | D5: Specialist | E5: Male | F5: 56 | G5: 08-08-2019 | I5: Active | J5: 970438.15 | K5: 5 | L5: 19.5 | M5: HND | N5: No
A6: EMP-4005 | B6: Tayo Adeleke | C6: Legal | D6: Director | E6: Male | F6: 58 | G6: 26-08-2021 | I6: Active | J6: 276446.95 | K6: 4 | L6: 0.3 | M6: BSc | N6: No
A7: EMP-4006 | B7: Amaka Musa | C7: Finance | D7: Executive | E7: Female | F7: 29 | G7: 09-06-2020 | H7: 01-02-2024 | I7: Terminated | J7: 159457.66 | K7: 4 | L7: 16.5 | M7: BSc | N7: Yes
A8: EMP-4007 | B8: Seun Okafor | C8: HR | D8: Analyst | E8: Woman | F8: 44 | G8: 29-07-2023 | H8: 17-04-2027 | I8: Resigned | J8: 168321.51 | K8: 4 | L8: 2.9 | M8: BSc | N8: Yes
A9: EMP-4008 | B9: Chidi Adeyemi | C9: HR | D9: Specialist | E9: Male | F9: 46 | G9: 02-09-2021 | I9: Active | J9: 1294403.7 | K9: 2 | L9: 5.2 | M9: BSc | N9: No
A10: EMP-4009 | B10: Tobi Osei | C10: IT | D10: Analyst | E10: Male | F10: 36 | G10: 06-10-2022 | I10: Active | J10: 618413.71 | K10: 5 | L10: 14.2 | M10: M.Sc | N10: No
A11: EMP-4010 | B11: Ngozi Nwosu | C11: HR | D11: Specialist | E11: Female | F11: 40 | G11: 13-01-2022 | I11: Active | J11: 724307.49 | K11: 2 | L11: 0.4 | M11: PhD | N11: No
A12: EMP-4011 | B12: Yusuf Adeleke | C12: Finance | D12: Senior Analyst | E12: Male | F12: 27 | G12: 11-09-2022 | H12: 18-01-2026 | I12: Resigned | J12: 1043804 | K12: 4 | L12: 3.3 | M12: PhD | N12: Yes
A13: EMP-4012 | B13: Zainab Abiodun | C13: Admin | D13: Associate | E13: Male | F13: 49 | G13: 29-09-2023 | I13: Active | J13: 1307309.8 | K13: 1 | L13: 17.2 | M13: HND | N13: No
A14: EMP-4013 | B14: Emeka Eze | C14: Operations | D14: Executive | E14: Female | F14: 55 | G14: 18-03-2021 | I14: Active | J14: 648584.73 | K14: 3 | L14: 7.6 | M14: OND | N14: No
A15: EMP-4014 | B15: Zainab Mohammed | C15: Operations | D15: Manager | E15: male | F15: 30 | G15: 07-01-2021 | H15: 31-05-2025 | I15: Resigned | J15: 381203.33 | K15: 5 | L15: 12.5 | M15: OND | N15: Yes
A16: EMP-4015 | B16: Chisom Adeleke | C16: Finance | D16: Manager | E16: Male | F16: 39 | G16: 16-06-2023 | I16: Active | K16: 3 | L16: 1.2 | M16: OND | N16: No
A17: EMP-4016 | B17: Sade Suleiman | C17: HR | D17: Coordinator | E17: Male | F17: 45 | G17: 19-07-2021 | H17: 04-03-2026 | I17: Resigned | J17: 146963.95 | K17: 2 | L17: 9.9 | M17: OND | N17: Yes
A18: EMP-4017 | B18: Yusuf Danjuma | C18: Finance | D18: Manager | E18: Male | F18: 46 | G18: 2023/05/20 | I18: Active | J18: 1387643 | K18: 3 | L18: 16.4 | M18: HND | N18: No
A19: EMP-4018 | B19: Tobi Mohammed | C19: HR | D19: Analyst | E19: Female | F19: 54 | G19: 04-01-2023 | I19: Active | J19: 1127352.9 | K19: 0 | L19: 10.8 | M19: MSC | N19: No
A20: EMP-4019 | B20: Emeka Musa | C20: Marketing | D20: Director | E20: Female | F20: 58 | G20: 13-06-2021 | H20: 09-02-2024 | I20: Resigned | J20: 650714.82 | K20: 1 | L20: 4.2 | M20: OND | N20: Yes
A21: EMP-4020 | B21: Zainab Garba | C21: Sales | D21: Associate | E21: Male | F21: 54 | G21: 23-10-2021 | I21: Active | J21: 992561.84 | K21: 3 | L21: 7.1 | M21: MSc | N21: No
A22: EMP-4021 | B22: Tobi Fashola | C22: IT | D22: Coordinator | E22: Woman | F22: 40 | G22: 12-09-2020 | I22: Active | J22: 1068312 | K22: 1 | L22: 9.6 | M22: BSc | N22: No
A23: EMP-4022 | B23: Jide Okafor | C23: IT | D23: Analyst | E23: Female | F23: 48 | G23: 04-06-2021 | I23: Active | J23: 955755.03 | K23: 4 | L23: 17.5 | M23: BSc
A24: EMP-4023 | B24: Olu Fashola | C24: Admin | D24: Specialist | E24: Female | F24: 32 | G24: 02-03-2021 | I24: Active | J24: 866969.06 | K24: 5 | L24: 15 | M24: BSc | N24: No
A25: EMP-4024 | B25: Sade Okafor | C25: Operations | D25: Specialist | E25: Female | F25: 58 | G25: 12-02-2019 | I25: Active | J25: 631365.7 | K25: 3 | L25: 13.1 | M25: OND | N25: No
A26: EMP-4025 | B26: Halima Fashola | C26: Sales | D26: Senior Analyst | E26: Male | F26: 50 | G26: 02-12-2022 | H26: 03-05-2024 | I26: Resigned | J26: 779793.35 | K26: 3 | L26: 6.9 | M26: BSc | N26: Yes
A27: EMP-4026 | B27: Jide Balogun | C27: IT | D27: Executive | E27: Female | F27: 23 | G27: 28-08-2021 | I27: Active | J27: 803839.55 | K27: 4 | L27: 4.6 | M27: OND | N27: No
A28: EMP-4027 | B28: Amaka Musa | C28: HR | D28: Associate | E28: Male | F28: 27 | G28: 04-03-2019 | I28: Active | J28: 588950.28 | K28: 4 | L28: 5.6 | M28: HND | N28: No
A29: EMP-4028 | B29: Yusuf Eze | C29: Sales | D29: Director | E29: M | F29: 58 | G29: 07-01-2023 | H29: 06-07-2024 | I29: Resigned | J29: 473873.91 | K29: 3 | L29: 1.1 | M29: OND | N29: Yes
A30: EMP-4029 | B30: Musa Mohammed | C30: Marketing | D30: Executive | E30: Female | F30: 52 | G30: 18-05-2020 | I30: Active | J30: 760893.91 | K30: 4 | L30: 14.5 | M30: OND | N30: No
A31: EMP-4030 | B31: Olu Ibrahim | C31: Sales | D31: Senior Analyst | E31: Male | F31: 53 | G31: 24-04-2020 | I31: Active | K31: 5 | L31: -1.2 | M31: HND | N31: No
A32: EMP-4031 | B32: Emeka Musa | C32: Sales | D32: Executive | E32: Male | F32: 23 | G32: 02-04-2019 | I32: Active | J32: 1434665.5 | K32: 2 | L32: 15.5 | M32: OND | N32: No
A33: EMP-4032 | B33: Chidi Danjuma | C33: HR | D33: Director | E33: Female | F33: 36 | G33: 18-05-2022 | I33: Active | J33: 1188750.1 | K33: 3 | L33: 6.6 | M33: BSc | N33: No
A34: EMP-4033 | B34: Emeka Musa | C34: Admin | D34: Senior Analyst | E34: Female | F34: 52 | G34: 18-04-2021 | I34: Active | J34: 122359.87 | K34: 1 | L34: 1 | M34: BSc | N34: No
A35: EMP-4034 | B35: Ada Musa | C35: Operations | D35: Specialist | E35: Male | F35: 39 | G35: 2021/05/16 | H35: 2024/12/02 | I35: Resigned | J35: 946761.29 | K35: 4 | L35: 0.7 | M35: HND | N35: Yes
A36: EMP-4035 | B36: Olu Osei | C36: HR | D36: Senior Analyst | E36: MALE | F36: 40 | G36: 24-08-2019 | H36: 15-03-2022 | I36: Terminated | J36: 101757.79 | K36: 3 | L36: 5.4 | M36: MSc | N36: Yes
A37: EMP-4036 | B37: Blessing Nwosu | C37: Sales | D37: Senior Analyst | E37: Male | F37: 57 | G37: 10-09-2022 | H37: 25-05-2027 | I37: Terminated | J37: 1299874.5 | K37: 0 | L37: 14.2 | M37: Bsc | N37: Yes
A38: EMP-4037 | B38: Chidi Danjuma | C38: Legal | D38: Director | E38: Female | F38: 30 | G38: 11-09-2019 | H38: 14-10-2020 | I38: Terminated | J38: 1385149 | K38: 2 | L38: 12.7 | M38: PhD | N38: Yes
A39: EMP-4038 | B39: Remi Nwosu | C39: Legal | D39: Manager | E39: Male | F39: 23 | G39: 29-08-2019 | I39: Active | J39: 118976.86 | K39: 3 | L39: 8.4 | M39: PhD | N39: No
A40: EMP-4039 | B40: Jide Balogun | C40: Marketing | D40: Senior Analyst | E40: Female | F40: 27 | G40: 25-12-2022 | I40: Active | J40: 1122494 | K40: 2 | L40: 15.4 | M40: PhD | N40: No
...

Sheet cleaned_data
A1: Employee_ID | B1: Full_Name | C1: Department | D1: Job_Title | E1: Gender | F1: Age | G1: Date_Hired | H1: Date_Left | I1: Employment_Status | J1: Performance_Score | K1: Column1 | L1: Years_Experience | M1: Education_Level | N1: Salary_NG | O1: Attrition | P1: Tenure_year | Q1: Age_Group | R1: Salary_bamd | S1: Hire_year
A2: EMP-4001 | B2: Jide Garba | C2: Marketing | D2: Director | E2: Male | F2: 29 | G2: 44065 | I2: Active | J2: 5 | L2: 4.8 | M2: OND | N2: 872210.52 | O2: No | P2: 5.8 | Q2: Under 30 | R2: High | S2: =YEAR(Cleaned_data[[#This Row],[Date_Hired]]) -> 2020
A3: EMP-4002 | B3: Tayo Okonkwo | C3: Operations | D3: Analyst | E3: Female | F3: 33 | G3: 45089 | H3: 46307 | I3: Terminated | J3: 3 | L3: 2.3 | M3: OND | N3: 339681.12 | O3: Yes | P3: 3.3 | Q3: 30-40 | R3: Mid | S3: =YEAR(Cleaned_data[[#This Row],[Date_Hired]]) -> 2023
A4: EMP-4003 | B4: Jide Musa | C4: Marketing | D4: Director | E4: Male | F4: 26 | G4: 43632 | H4: 45239 | I4: Terminated | J4: 5 | L4: 1.5 | M4: MSc | N4: 925355.42 | O4: Yes | P4: 4.4 | Q4: Under 30 | R4: High | S4: =YEAR(Cleaned_data[[#This Row],[Date_Hired]]) -> 2019
A5: EMP-4004 | B5: Emeka Mohammed | C5: HR | D5: Specialist | E5: Male | F5: 56 | G5: 43685 | I5: Active | J5: 5 | L5: 19.5 | M5: HND | N5: 970438.15 | O5: No | P5: 6.8 | Q5: Above 50 | R5: High | S5: =YEAR(Cleaned_data[[#This Row],[Date_Hired]]) -> 2019
A6: EMP-4005 | B6: Tayo Adeleke | C6: Legal | D6: Director | E6: Male | F6: 58 | G6: 44434 | I6: Active | J6: 4 | L6: 0.3 | M6: BSc | N6: 276446.95 | O6: No | P6: 4.8 | Q6: Above 50 | R6: Low | S6: =YEAR(Cleaned_data[[#This Row],[Date_Hired]]) -> 2021
A7: EMP-4006 | B7: Amaka Musa | C7: Finance | D7: Executive | E7: Female | F7: 29 | G7: 43991 | H7: 45323 | I7: Terminated | J7: 4 | L7: 16.5 | M7: BSc | N7: 159457.66 | O7: Yes | P7: 3.6 | Q7: Under 30 | R7: Low | S7: =YEAR(Cleaned_data[[#This Row],[Date_Hired]]) -> 2020
A8: EMP-4007 | B8: Seun Okafor | C8: HR | D8: Analyst | E8: Female | F8: 44 | G8: 45136 | H8: 46494 | I8: Resigned | J8: 4 | L8: 2.9 | M8: BSc | N8: 168321.51 | O8: Yes | P8: 3.7 | Q8: 41-50 | R8: Low | S8: =YEAR(Cleaned_data[[#This Row],[Date_Hired]]) -> 2023
A9: EMP-4008 | B9: Chidi Adeyemi | C9: HR | D9: Specialist | E9: Male | F9: 46 | G9: 44441 | I9: Active | J9: 2 | L9: 5.2 | M9: BSc | N9: 1294403.7 | O9: No | P9: 4.7 | Q9: 41-50 | R9: Very High | S9: =YEAR(Cleaned_data[[#This Row],[Date_Hired]]) -> 2021
A10: EMP-4009 | B10: Tobi Osei | C10: IT | D10: Analyst | E10: Male | F10: 36 | G10: 44840 | I10: Active | J10: 5 | L10: 14.2 | M10: MSc | N10: 618413.71 | O10: No | P10: 3.6 | Q10: 30-40 | R10: Mid | S10: =YEAR(Cleaned_data[[#This Row],[Date_Hired]]) -> 2022
A11: EMP-4010 | B11: Ngozi Nwosu | C11: HR | D11: Specialist | E11: Female | F11: 40 | G11: 44574 | I11: Active | J11: 2 | L11: 0.4 | M11: PhD | N11: 724307.49 | O11: No | P11: 4.4 | Q11: 30-40 | R11: High | S11: =YEAR(Cleaned_data[[#This Row],[Date_Hired]]) -> 2022
A12: EMP-4011 | B12: Yusuf Adeleke | C12: Finance | D12: Senior Analyst | E12: Male | F12: 27 | G12: 44815 | H12: 46040 | I12: Resigned | J12: 4 | L12: 3.3 | M12: PhD | N12: 1043804 | O12: Yes | P12: 3.4 | Q12: Under 30 | R12: Very High | S12: =YEAR(Cleaned_data[[#This Row],[Date_Hired]]) -> 2022
A13: EMP-4012 | B13: Zainab Abiodun | C13: Admin | D13: Associate | E13: Male | F13: 49 | G13: 45198 | I13: Active | J13: 1 | L13: 17.2 | M13: HND | N13: 1307309.8 | O13: No | P13: 2.7 | Q13: 41-50 | R13: Very High | S13: =YEAR(Cleaned_data[[#This Row],[Date_Hired]]) -> 2023
A14: EMP-4013 | B14: Emeka Eze | C14: Operations | D14: Executive | E14: Female | F14: 55 | G14: 44273 | I14: Active | J14: 3 | L14: 7.6 | M14: OND | N14: 648584.73 | O14: No | P14: 5.2 | Q14: Above 50 | R14: Mid | S14: =YEAR(Cleaned_data[[#This Row],[Date_Hired]]) -> 2021
A15: EMP-4014 | B15: Zainab Mohammed | C15: Operations | D15: Manager | E15: Male | F15: 30 | G15: 44203 | H15: 45808 | I15: Resigned | J15: 5 | L15: 12.5 | M15: OND | N15: 381203.33 | O15: Yes | P15: 4.4 | Q15: 30-40 | R15: Mid | S15: =YEAR(Cleaned_data[[#This Row],[Date_Hired]]) -> 2021
A16: EMP-4015 | B16: Chisom Adeleke | C16: Finance | D16: Manager | E16: Male | F16: 39 | G16: 45093 | I16: Active | J16: 3 | L16: 1.2 | M16: OND | N16: 718000 | O16: No | P16: 2.9 | Q16: 30-40 | R16: High | S16: =YEAR(Cleaned_data[[#This Row],[Date_Hired]]) -> 2023
A17: EMP-4016 | B17: Sade Suleiman | C17: HR | D17: Coordinator | E17: Male | F17: 45 | G17: 44396 | H17: 46085 | I17: Resigned | J17: 2 | L17: 9.9 | M17: OND | N17: 146963.95 | O17: Yes | P17: 4.6 | Q17: 41-50 | R17: Low | S17: =YEAR(Cleaned_data[[#This Row],[Date_Hired]]) -> 2021
A18: EMP-4017 | B18: Yusuf Danjuma | C18: Finance | D18: Manager | E18: Male | F18: 46 | G18: 45066 | I18: Active | J18: 3 | L18: 16.4 | M18: HND | N18: 1387643 | O18: No | P18: 3 | Q18: 41-50 | R18: Very High | S18: =YEAR(Cleaned_data[[#This Row],[Date_Hired]]) -> 2023
A19: EMP-4018 | B19: Tobi Mohammed | C19: HR | D19: Analyst | E19: Female | F19: 54 | G19: 44930 | I19: Active | J19: 0 | L19: 10.8 | M19: MSc | N19: 1127352.9 | O19: No | P19: 3.4 | Q19: Above 50 | R19: Very High | S19: =YEAR(Cleaned_data[[#This Row],[Date_Hired]]) -> 2023
A20: EMP-4019 | B20: Emeka Musa | C20: Marketing | D20: Director | E20: Female | F20: 58 | G20: 44360 | H20: 45331 | I20: Resigned | J20: 1 | L20: 4.2 | M20: OND | N20: 650714.82 | O20: Yes | P20: 2.7 | Q20: Above 50 | R20: Mid | S20: =YEAR(Cleaned_data[[#This Row],[Date_Hired]]) -> 2021
A21: EMP-4020 | B21: Zainab Garba | C21: Sales | D21: Associate | E21: Male | F21: 54 | G21: 44492 | I21: Active | J21: 3 | L21: 7.1 | M21: MSc | N21: 992561.84 | O21: No | P21: 4.6 | Q21: Above 50 | R21: High | S21: =YEAR(Cleaned_data[[#This Row],[Date_Hired]]) -> 2021
A22: EMP-4021 | B22: Tobi Fashola | C22: IT | D22: Coordinator | E22: Female | F22: 40 | G22: 44086 | I22: Active | J22: 1 | L22: 9.6 | M22: BSc | N22: 1068312 | O22: No | P22: 5.7 | Q22: 30-40 | R22: Very High | S22: =YEAR(Cleaned_data[[#This Row],[Date_Hired]]) -> 2020
A23: EMP-4022 | B23: Jide Okafor | C23: IT | D23: Analyst | E23: Female | F23: 48 | G23: 44351 | I23: Active | J23: 4 | L23: 17.5 | M23: BSc | N23: 955755.03 | O23: No | P23: 5 | Q23: 41-50 | R23: High | S23: =YEAR(Cleaned_data[[#This Row],[Date_Hired]]) -> 2021
A24: EMP-4023 | B24: Olu Fashola | C24: Admin | D24: Specialist | E24: Female | F24: 32 | G24: 44257 | I24: Active | J24: 5 | L24: 15 | M24: BSc | N24: 866969.06 | O24: No | P24: 5.2 | Q24: 30-40 | R24: High | S24: =YEAR(Cleaned_data[[#This Row],[Date_Hired]]) -> 2021
A25: EMP-4024 | B25: Sade Okafor | C25: Operations | D25: Specialist | E25: Female | F25: 58 | G25: 43508 | I25: Active | J25: 3 | L25: 13.1 | M25: OND | N25: 631365.7 | O25: No | P25: 7.3 | Q25: Above 50 | R25: Mid | S25: =YEAR(Cleaned_data[[#This Row],[Date_Hired]]) -> 2019
A26: EMP-4025 | B26: Halima Fashola | C26: Sales | D26: Senior Analyst | E26: Male | F26: 50 | G26: 44897 | H26: 45415 | I26: Resigned | J26: 3 | L26: 6.9 | M26: BSc | N26: 779793.35 | O26: Yes | P26: 1.4 | Q26: 41-50 | R26: High | S26: =YEAR(Cleaned_data[[#This Row],[Date_Hired]]) -> 2022
A27: EMP-4026 | B27: Jide Balogun | C27: IT | D27: Executive | E27: Female | F27: 23 | G27: 44436 | I27: Active | J27: 4 | L27: 4.6 | M27: OND | N27: 803839.55 | O27: No | P27: 4.7 | Q27: Under 30 | R27: High | S27: =YEAR(Cleaned_data[[#This Row],[Date_Hired]]) -> 2021
A28: EMP-4027 | B28: Amaka Musa | C28: HR | D28: Associate | E28: Male | F28: 27 | G28: 43528 | I28: Active | J28: 4 | L28: 5.6 | M28: HND | N28: 588950.28 | O28: No | P28: 7.2 | Q28: Under 30 | R28: Mid | S28: =YEAR(Cleaned_data[[#This Row],[Date_Hired]]) -> 2019
A29: EMP-4028 | B29: Yusuf Eze | C29: Sales | D29: Director | E29: Male | F29: 58 | G29: 44933 | H29: 45479 | I29: Resigned | J29: 3 | L29: 1.1 | M29: OND | N29: 473873.91 | O29: Yes | P29: 1.5 | Q29: Above 50 | R29: Mid | S29: =YEAR(Cleaned_data[[#This Row],[Date_Hired]]) -> 2023
A30: EMP-4029 | B30: Musa Mohammed | C30: Marketing | D30: Executive | E30: Female | F30: 52 | G30: 43969 | I30: Active | J30: 4 | L30: 14.5 | M30: OND | N30: 760893.91 | O30: No | P30: 6 | Q30: Above 50 | R30: High | S30: =YEAR(Cleaned_data[[#This Row],[Date_Hired]]) -> 2020
A31: EMP-4030 | B31: Olu Ibrahim | C31: Sales | D31: Senior Analyst | E31: Male | F31: 53 | G31: 43945 | I31: Active | J31: 5 | L31: -1.2 | M31: HND | N31: 718000 | O31: No | P31: 6.1 | Q31: Above 50 | R31: High | S31: =YEAR(Cleaned_data[[#This Row],[Date_Hired]]) -> 2020
A32: EMP-4031 | B32: Emeka Musa | C32: Sales | D32: Executive | E32: Male | F32: 23 | G32: 43557 | I32: Active | J32: 2 | L32: 15.5 | M32: OND | N32: 1434665.5 | O32: No | P32: 7.2 | Q32: Under 30 | R32: Very High | S32: =YEAR(Cleaned_data[[#This Row],[Date_Hired]]) -> 2019
A33: EMP-4032 | B33: Chidi Danjuma | C33: HR | D33: Director | E33: Female | F33: 36 | G33: 44699 | I33: Active | J33: 3 | L33: 6.6 | M33: BSc | N33: 1188750.1 | O33: No | P33: 4 | Q33: 30-40 | R33: Very High | S33: =YEAR(Cleaned_data[[#This Row],[Date_Hired]]) -> 2022
A34: EMP-4033 | B34: Emeka Musa | C34: Admin | D34: Senior Analyst | E34: Female | F34: 52 | G34: 44304 | I34: Active | J34: 1 | L34: 1 | M34: BSc | N34: 122359.87 | O34: No | P34: 5.1 | Q34: Above 50 | R34: Low | S34: =YEAR(Cleaned_data[[#This Row],[Date_Hired]]) -> 2021
A35: EMP-4034 | B35: Ada Musa | C35: Operations | D35: Specialist | E35: Male | F35: 39 | G35: 44332 | H35: 45628 | I35: Resigned | J35: 4 | L35: 0.7 | M35: HND | N35: 946761.29 | O35: Yes | P35: 3.6 | Q35: 30-40 | R35: High | S35: =YEAR(Cleaned_data[[#This Row],[Date_Hired]]) -> 2021
A36: EMP-4035 | B36: Olu Osei | C36: HR | D36: Senior Analyst | E36: Male | F36: 40 | G36: 43701 | H36: 44635 | I36: Terminated | J36: 3 | L36: 5.4 | M36: MSc | N36: 101757.79 | O36: Yes | P36: 2.6 | Q36: 30-40 | R36: Low | S36: =YEAR(Cleaned_data[[#This Row],[Date_Hired]]) -> 2019
A37: EMP-4036 | B37: Blessing Nwosu | C37: Sales | D37: Senior Analyst | E37: Male | F37: 57 | G37: 44814 | H37: 46532 | I37: Terminated | J37: 0 | L37: 14.2 | M37: BSc | N37: 1299874.5 | O37: Yes | P37: 4.7 | Q37: Above 50 | R37: Very High | S37: =YEAR(Cleaned_data[[#This Row],[Date_Hired]]) -> 2022
A38: EMP-4037 | B38: Chidi Danjuma | C38: Legal | D38: Director | E38: Female | F38: 30 | G38: 43719 | H38: 44118 | I38: Terminated | J38: 2 | L38: 12.7 | M38: PhD | N38: 1385149 | O38: Yes | P38: 1.1 | Q38: 30-40 | R38: Very High | S38: =YEAR(Cleaned_data[[#This Row],[Date_Hired]]) -> 2019
A39: EMP-4038 | B39: Remi Nwosu | C39: Legal | D39: Manager | E39: Male | F39: 23 | G39: 43706 | I39: Active | J39: 3 | L39: 8.4 | M39: PhD | N39: 118976.86 | O39: No | P39: 6.7 | Q39: Under 30 | R39: Low | S39: =YEAR(Cleaned_data[[#This Row],[Date_Hired]]) -> 2019
A40: EMP-4039 | B40: Jide Balogun | C40: Marketing | D40: Senior Analyst | E40: Female | F40: 27 | G40: 44920 | I40: Active | J40: 2 | L40: 15.4 | M40: PhD | N40: 1122494 | O40: No | P40: 3.4 | Q40: Under 30 | R40: Very High | S40: =YEAR(Cleaned_data[[#This Row],[Date_Hired]]) -> 2022
...

Sheet Dim_salary
A1: Employee_ID | B1: Date_Hired | C1: Salary_NG | D1: Salary_band
A2: EMP-4001 | B2: 44065 | C2: 872210.52 | D2: High
A3: EMP-4002 | B3: 45089 | C3: 339681.12 | D3: Mid
A4: EMP-4003 | B4: 43632 | C4: 925355.42 | D4: High
A5: EMP-4004 | B5: 43685 | C5: 970438.15 | D5: High
A6: EMP-4005 | B6: 44434 | C6: 276446.95 | D6: Low
A7: EMP-4006 | B7: 43991 | C7: 159457.66 | D7: Low
A8: EMP-4007 | B8: 45136 | C8: 168321.51 | D8: Low
A9: EMP-4008 | B9: 44441 | C9: 1294403.7 | D9: Very High
A10: EMP-4009 | B10: 44840 | C10: 618413.71 | D10: Mid
A11: EMP-4010 | B11: 44574 | C11: 724307.49 | D11: High
A12: EMP-4011 | B12: 44815 | C12: 1043804 | D12: Very High
A13: EMP-4012 | B13: 45198 | C13: 1307309.8 | D13: Very High
... A201: EMP-4200 | B201: 44993 | C201: 978536.82 | D201: High

Sheet pivot_table
A1: Row Labels | B1: Count of Employee_ID | D1: Count of Employee_ID | E1: Column Labels | I1: Row Labels | J1: Count of Employee_ID
A2: IT | B2: 13 | D2: Row Labels | E2: No | F2: Yes | G2: Grand Total | I2: 0 | J2: 1 | M2: Row Labels | N2: Sum of Salary_NG
A3: Sales | B3: 5 | D3: Admin | F3: 1 | G3: 1 | I3: 1 | J3: 4 | M3: 30-40 | N3: 0.30933796
A4: Finance | B4: 4 | D4: Finance | E4: 1 | F4: 3 | G4: 4 | I4: 2 | J4: 10 | M4: 41-50 | N4: 0.28891155
A5: HR | B5: 3 | D5: HR | E5: 1 | F5: 2 | G5: 3 | I5: 3 | J5: 2 | M5: Above 50 | N5: 0.22901253
A6: Marketing | B6: 3 | D6: IT | E6: 7 | F6: 6 | G6: 13 | I6: 4 | J6: 5 | M6: Under 30 | N6: 0.17273796
A7: Legal | B7: 2 | D7: Legal | E7: 1 | F7: 1 | G7: 2 | I7: 5 | J7: 8 | M7: Grand Total | N7: 1
A8: Admin | B8: 1 | D8: Marketing | E8: 3 | G8: 3 | I8: 10 | J8: 1
A9: Grand Total | B9: 31 | D9: Sales | E9: 2 | F9: 3 | G9: 5 | I9: Grand Total | J9: 31
D10: Grand Total | E10: 15 | F10: 16 | G10: 31
K11: Row Labels | L11: Count of Employee_ID
K12: 2019 | L12: 44
A13: Row Labels | B13: Average of Salary_NG | D13: Row Labels | E13: Count of Employee_ID | H13: Row Labels | I13: Count of Employee_ID | K13: 2020 | L13: 31
A14: Specialist | B14: 845290.25 | D14: Female | E14: 0.67741935 | H14: 30-40 | I14: 12 | K14: 2021 | L14: 56
A15: Coordinator | B15: 744362.17 | D15: Male | E15: 0.32258065 | H15: 41-50 | I15: 8 | K15: 2022 | L15: 39
A16: Executive | B16: 637477.07 | D16: Grand Total | E16: 1 | H16: Above 50 | I16: 6 | K16: 2023 | L16: 30
A17: Manager | B17: 613145.45 | H17: Under 30 | I17: 5 | K17: Grand Total | L17: 200
A18: Analyst | B18: 600227.46 | E18: Average of Salary_NG2 | H18: Grand Total | I18: 31
A19: Director | B19: 583367.98 | D19: Finance | E19: 468764.03 | K19: Row Labels | L19: Sum of Performance_Score
A20: Senior Analyst | B20: 563990.11 | D20: Sales | E20: 496933.75 | H20: Row Labels | I20: Count of Employee_ID | K20: 2019 | L20: 142
A21: Associate | B21: 549020.37 | D21: Admin | E21: 552212.23 | H21: Very High | I21: 4 | K21: 2020 | L21: 100
A22: Grand Total | B22: 650560.42 | D22: IT | E22: 689411.48 | H22: Mid | I22: 11 | K22: 2021 | L22: 151
D23: Marketing | E23: 736419.13 | H23: Low | I23: 5 | K23: 2022 | L23: 116
A24: Row Labels | B24: Average of Salary_NG | D24: HR | E24: 790848.59 | H24: High | I24: 11 | K24: 2023 | L24: 75
A25: PhD | B25: 838088.41 | D25: Legal | E25: 855641.84 | H25: Grand Total | I25: 31 | K25: Grand Total | L25: 584
A26: HND | B26: 784817.82 | D26: Grand Total | E26: 650560.42
A27: BSc | B27: 664223.81 | H27: Row Labels | I27: Count of Employee_ID
A28: OND | B28: 647351.8 | H28: Active | I28: 0.48387097
A29: MSc | B29: 483361.71 | H29: Resigned | I29: 0.22580645
A30: Grand Total | B30: 650560.42 | H30: Terminated | I30: 0.29032258
H31: Grand Total | I31: 1

Sheet workforce

Sheet performance

Sheet Dim_Department
A1: DepartmentID | B1: DepartmentName | C1: DepartmentHead
A2: D001 | B2: HR | C2: TBD
A3: D002 | B3: Finance | C3: TBD
A4: D003 | B4: IT | C4: TBD
A5: D004 | B5: Marketing | C5: TBD
A6: D005 | B6: Operations | C6: TBD
A7: D006 | B7: Sales | C7: TBD
A8: D007 | B8: Legal | C8: TBD
A9: D008 | B9: Admin | C9: TB

Sheet Dim_Performance
A1: Employee_ID | B1: Performance_Score | C1: Years_Experience | D1: Attrition
A2: EMP-4001 | B2: 5 | C2: 4.8 | D2: No
A3: EMP-4002 | B3: 3 | C3: 2.3 | D3: Yes
A4: EMP-4003 | B4: 5 | C4: 1.5 | D4: Yes
A5: EMP-4004 | B5: 5 | C5: 19.5 | D5: No
A6: EMP-4005 | B6: 4 | C6: 0.3 | D6: No
A7: EMP-4006 | B7: 4 | C7: 16.5 | D7: Yes
A8: EMP-4007 | B8: 4 | C8: 2.9 | D8: Yes
A9: EMP-4008 | B9: 2 | C9: 5.2 | D9: No
A10: EMP-4009 | B10: 5 | C10: 14.2 | D10: No
A11: EMP-4010 | B11: 2 | C11: 0.4 | D11: No
A12: EMP-4011 | B12: 4 | C12: 3.3 | D12: Yes
A13: EMP-4012 | B13: 1 | C13: 17.2 | D13: No
... A201: EMP-4200 | B201: 5 | C201: 6.1 | D201: Yes

Sheet Summary_Template
A1: HR DATA ANALYSIS — SUMMARY
A3: Metric | B3: Value / Formula
A4: Total Employees | B4: =COUNTA(Raw_HR_Data!A2:A201) -> 200
A5: Active Employees | B5: =COUNTIF(Raw_HR_Data!I2:I201,"Active") -> 119
A6: Attrition Count | B6: =COUNTIF(Raw_HR_Data!N2:N201,"Yes") -> 76
A7: Attrition Rate | B7: =COUNTIF(Raw_HR_Data!N2:N201,"Yes")/COUNTA(Raw_HR_Data!N2:N201) -> 0.39790576
A8: Avg Salary (NGN) | B8: =AVERAGEIF(Raw_HR_Data!J2:J201,">0",Raw_HR_Data!J2:J201) -> 720004.67
A9: Avg Performance Score | B9: =AVERAGEIF(Raw_HR_Data!K2:K201,"<=5",Raw_HR_Data!K2:K201) -> 2.8121827
A10: Avg Years Experience | B10: =AVERAGEIF(Raw_HR_Data!L2:L201,">=0",Raw_HR_Data!L2:L201) -> 9.3515464
A11: Largest Department | B11: Use COUNTIF after cleaning
A12: Top Education Level | B12: Use COUNTIF after cleaning
